<?xml version="1.0" encoding="utf-8"?>
<!-- This URDF was automatically created by SolidWorks to URDF Exporter! Originally created by Stephen Brawner (brawner@gmail.com) 
     Commit Version: 1.6.0-4-g7f85cfe  Build Version: 1.6.7995.38578
     For more information, please see http://wiki.ros.org/sw_urdf_exporter -->
<robot name="i608">
	<link name="base_link">
		<visual>
			<origin xyz="0 0 0" rpy="0 0 0" />
			<geometry>
				<mesh filename="package://icnc_resources_i608_description/meshes/base_link.STL" />
			</geometry>
			<material name="">
				<color rgba="0.2 0.2 0.2 1" />
			</material>
		</visual>
		<collision>
			<origin xyz="0 0 0" rpy="0 0 0" />
			<geometry>
				<mesh filename="package://icnc_resources_i608_description/meshes/base_link.STL" />
			</geometry>
		</collision>
	</link>
	<link name="link_2">
		<visual>
			<origin xyz="0 0 0" rpy="0 0 0" />
			<geometry>
				<mesh filename="package://icnc_resources_i608_description/meshes/link_2.STL" />
			</geometry>
			<material name="">
				<color rgba="0.64706 0.61961 0.58824 1" />
			</material>
		</visual>
		<collision>
			<origin xyz="0 0 0" rpy="0 0 0" />
			<geometry>
				<mesh filename="package://icnc_resources_i608_description/meshes/link_2.STL" />
			</geometry>
		</collision>
	</link>
	<joint name="joint_1" type="revolute">
		<origin xyz="0 0 0.17" rpy="0 0 0" />
		<parent link="base_link" />
		<child link="link_2" />
		<axis xyz="0 0 1" />
		<limit lower="-2.8798" upper="2.8798" effort="0" velocity="0" />
	</joint>
	<link name="link_3">
		<visual>
			<origin xyz="0 0 0" rpy="0 0 0" />
			<geometry>
				<mesh filename="package://icnc_resources_i608_description/meshes/link_3.STL" />
			</geometry>
			<material name="">
				<color rgba="0.64706 0.61961 0.58824 1" />
			</material>
		</visual>
		<collision>
			<origin xyz="0 0 0" rpy="0 0 0" />
			<geometry>
				<mesh filename="package://icnc_resources_i608_description/meshes/link_3.STL" />
			</geometry>
		</collision>
	</link>
	<joint name="joint_2" type="revolute">
		<origin xyz="-0.16933 0.098418 0.21503" rpy="-1.5708 0 3.1416" />
		<parent link="link_2" />
		<child link="link_3" />
		<axis xyz="0 0 1" />
		<limit lower="-2.7053" upper="1.5708" effort="0" velocity="0" />
	</joint>
	<link name="link_4">
		<visual>
			<origin xyz="0 0 0" rpy="0 0 0" />
			<geometry>
				<mesh filename="package://icnc_resources_i608_description/meshes/link_4.STL" />
			</geometry>
			<material name="">
				<color rgba="0.64706 0.61961 0.58824 1" />
			</material>
		</visual>
		<collision>
			<origin xyz="0 0 0" rpy="0 0 0" />
			<geometry>
				<mesh filename="package://icnc_resources_i608_description/meshes/link_4.STL" />
			</geometry>
		</collision>
	</link>
	<joint name="joint_3" type="revolute">
		<origin xyz="0 -0.625 0" rpy="1.5708 0 -1.5708" />
		<parent link="link_3" />
		<child link="link_4" />
		<axis xyz="0 1 0" />
		<limit lower="-1.2217" upper="3.8397" effort="0" velocity="0" />
	</joint>
	<link name="link_5">
		<visual>
			<origin xyz="0 0 0" rpy="0 0 0" />
			<geometry>
				<mesh filename="package://icnc_resources_i608_description/meshes/link_5.STL" />
			</geometry>
			<material name="">
				<color rgba="0.64706 0.61961 0.58824 1" />
			</material>
		</visual>
		<collision>
			<origin xyz="0 0 0" rpy="0 0 0" />
			<geometry>
				<mesh filename="package://icnc_resources_i608_description/meshes/link_5.STL" />
			</geometry>
		</collision>
	</link>
	<joint name="joint_4" type="revolute">
		<origin xyz="0.13 0.064918 -0.191" rpy="-1.5708 0 0" />
		<parent link="link_4" />
		<child link="link_5" />
		<axis xyz="0 1 0" />
		<limit lower="-2.9671" upper="2.9671" effort="0" velocity="0" />
	</joint>
	<link name="link_6">
		<visual>
			<origin xyz="0 0 0" rpy="0 0 0" />
			<geometry>
				<mesh filename="package://icnc_resources_i608_description/meshes/link_6.STL" />
			</geometry>
			<material name="">
				<color rgba="1 1 1 1" />
			</material>
		</visual>
		<collision>
			<origin xyz="0 0 0" rpy="0 0 0" />
			<geometry>
				<mesh filename="package://icnc_resources_i608_description/meshes/link_6.STL" />
			</geometry>
		</collision>
	</link>
	<joint name="joint_5" type="revolute">
		<origin xyz="0 0.459 0" rpy="0 0 3.1416" />
		<parent link="link_5" />
		<child link="link_6" />
		<axis xyz="0 0 1" />
		<limit lower="-2.0944" upper="2.0944" effort="0" velocity="0" />
	</joint>
	<link name="gripper">
		<visual>
			<origin xyz="0 0 0" rpy="0 0 0" />
			<geometry>
				<mesh filename="package://icnc_resources_i608_description/meshes/gripper.STL" />
			</geometry>
			<material name="">
				<color rgba="0.75294 0.75294 0.75294 1" />
			</material>
		</visual>
		<collision>
			<origin xyz="0 0 0" rpy="0 0 0" />
			<geometry>
				<mesh filename="package://icnc_resources_i608_description/meshes/gripper.STL" />
			</geometry>
		</collision>
	</link>
	<joint name="joint_6" type="continuous">
		<origin xyz="0 -0.1216 0.0004" rpy="1.5549 1.5708 0" />
		<parent link="link_6" />
		<child link="gripper" />
		<axis xyz="0 0.015937 0.99987" />
	</joint>

	<ros2_control name="I608SystemPV" type="system">
		<hardware>
			<plugin>icnc_hardware_interfaces/I608FakeHardwareInterface</plugin>
		</hardware>
		<joint name="joint_1">
			<command_interface name="position"></command_interface>
			<command_interface name="velocity"></command_interface>
			<state_interface name="position"></state_interface>
			<state_interface name="velocity"></state_interface>
		</joint>
		<joint name="joint_2">
			<command_interface name="position"></command_interface>
			<command_interface name="velocity"></command_interface>
			<state_interface name="position"></state_interface>
			<state_interface name="velocity"></state_interface>
		</joint>
		<joint name="joint_3">
			<command_interface name="position"></command_interface>
			<command_interface name="velocity"></command_interface>
			<state_interface name="position"></state_interface>
			<state_interface name="velocity"></state_interface>
		</joint>
		<joint name="joint_4">
			<command_interface name="position"></command_interface>
			<command_interface name="velocity"></command_interface>
			<state_interface name="position"></state_interface>
			<state_interface name="velocity"></state_interface>
		</joint>
		<joint name="joint_5">
			<command_interface name="position"></command_interface>
			<command_interface name="velocity"></command_interface>
			<state_interface name="position"></state_interface>
			<state_interface name="velocity"></state_interface>
		</joint>
		<joint name="joint_6">
			<command_interface name="position"></command_interface>
			<command_interface name="velocity"></command_interface>
			<state_interface name="position"></state_interface>
			<state_interface name="velocity"></state_interface>
		</joint>
	</ros2_control>
</robot>